2020-07-27 01:38:59,813 DEBUG   MainThread:18484 [util.py:is_cygwin_git():314] Failed checking if running in CYGWIN due to: FileNotFoundError(2, 'The system cannot find the file specified', None, 2, None)
2020-07-27 01:38:59,815 DEBUG   MainThread:18484 [git_repo.py:repo():28] git repository is invalid
2020-07-27 01:38:59,817 DEBUG   MainThread:18484 [connectionpool.py:_new_conn():824] Starting new HTTPS connection (1): pypi.org
2020-07-27 01:39:00,408 DEBUG   MainThread:18484 [connectionpool.py:_make_request():396] https://pypi.org:443 "GET /pypi/wandb-ng/json HTTP/1.1" 200 11346
2020-07-27 01:39:00,417 INFO    wandb_write:18484 [datastore.py:open_for_write():76] open: .\wandb\runs\run-20200727_013858-2pho65k9\run-20200727_013858-2pho65k9.wandb
2020-07-27 01:39:00,430 DEBUG   wandb_send:18484 [connectionpool.py:_new_conn():824] Starting new HTTPS connection (1): api.wandb.ai
2020-07-27 01:39:00,540 DEBUG   wandb_send:18484 [connectionpool.py:_make_request():396] https://api.wandb.ai:443 "POST /graphql HTTP/1.1" 401 None
2020-07-27 01:39:00,545 ERROR   wandb_send:18484 [internal_api.py:execute():118] 401 response executing GraphQL.
2020-07-27 01:39:00,545 ERROR   wandb_send:18484 [internal_api.py:execute():119] {"errors":[{"message":"permission denied","path":["upsertBucket"],"extensions":{"code":"PERMISSION_ERROR"}}],"data":{"upsertBucket":null}}
